<robot name="donkeycar">
    <link name="base_link" />
    <link name="base_footprint" />
    <link name="lidar_link" />
    <link name="camera_link" />
    <link name="imu_link" />
    <link name="map" />

    <joint name="base_footprint_joint" type="fixed">
        <parent link="base_link" />
        <child link="base_footprint" />
        <origin xyz="0 0 0" rpy="0 0 0" />
    </joint>

    <joint name="lidar_joint" type="fixed">
        <parent link="base_link" />
        <child link="lidar_link" />
        <origin xyz="0 0 0" rpy="0 0 0" />
    </joint>

    <joint name="camera_joint" type="fixed">
        <parent link="base_link" />
        <child link="camera_link" />
        <origin xyz="0 0 0" rpy="0 0 0" />
    </joint>

    <joint name="imu_joint" type="fixed">
        <parent link="base_link" />
        <child link="imu_link" />
        <origin xyz="0 0 0" rpy="0 0 0" />
    </joint>

    <joint name="map_joint" type="floating">
        <parent link="base_link" />
        <child link="map" />
        <origin xyz="0 0 0" rpy="0 0 0" />
    </joint>
</robot>